Workbook

Sheet Sheet1
A1: FORM NO.16
A2: [See rule 31 (1) (a)]
A3: Part A
A4: Certificate under section 203 of the Income Tax Act, 1961 for tax deducted
A5: at source from income chargeable under the head “ Salaries “
A7: Name and address of the employer | G7: Name and Designation of the employee
A8: I Smart Facitech Private Ltd
A9: 317, 3rd Floor,A/2 , Neelgiri Bldg,
A10: Wadala Truck Terminal Near Wadala RTO,
A11: Mumbai -400037
A12: PAN of the Deducter | D12: TAN of the Deducter | G12: PAN of the Employee
A13: AAKCC4528J | D13: MUMC28808D | G13: {{EMP_PAN}}
A14: TDS Circle where annual | G14: PERIOD | J14: Assessment Year
A15: return / statement under | G15: FROM | I15: TO | J15: 2026-27
A16: section 206 is to be filed | G16: 45748 | I16: 45930
A17: Smmary of amount Paid/credited and tax Deducted at source thereon in respect of the Employee
A18: Quarter(s) | C18: Receipt Numbersof Original Quaterly Statements of TDS Under Sub-Section (3) of Section 200 | F18: Amount Paid cridited | H18: Amount of Tax Deducted (Rs) | K18: Amount of Tax Deposited / Remitted (Rs)
A19: Quarter 1 | K19: 0
A20: Quarter 2 | K20: 0
A21: Quarter 3 | K21: 0
A22: Quarter 4 | K22: 0
A23: Total | F23: 0 | H23: 0 | K23: 0
A24: I.DETAILS TAX DEDUCTED AND DEPOSITED INTO CENTRAL GOVERNMENT ACCOUNT THROUGH BOOK ADJUSTMENT
A25: S.No | B25: Tax Deposited In Respect | E25: Book Identification Number (BIN)
B26: of the deducter | E26: Receipt Numbers of | G26: DDO Serial No in | I26: Date Of Transfer | K26: Status of Maching
C27: (Rs) | E27: Form No.24G | G27: Form No.24G | I27: Form No.24G | K27: with Form.No 24G
I28: (dd/mm/yyyy)
A29: 1
A30: 2
A31: 3
A32: 4
A33: 5
A34: 6
A35: 7
A36: 8
A37: 9
A38: 10
A39: 11
A40: 12
A41: Total (Rs) | B41: 0
...

Sheet __CALC__

Sheet DATA
A1: Field | B1: Value
A2: Gross Salary | B2: 0
A3: Professional Tax | B3: 0
A4: PF Annual | B4: 0
A5: Other Income | B5: 0
A6: Total TDS | B6: 0
A7: Tax Calculated | B7: 0
A8: EMP_NAME
A9: EMP_DESIGNATION
